Workbook
Name DATA1: #REF!
Name DATA2: #REF!
Name DATA3: #REF!
Name DATA4: #REF!
Name TEST0: #REF!
Name TESTHKEY: #REF!
Name TESTKEYS: #REF!
Name TESTVKEY: #REF!

Sheet DISPONIBILIDAD 
A1: CODIGO LAMINA | B1: LAMINA 0,195 VIRGEN | C1: STEEL FORCE | D1: JINTAI | E1: SUXUN | F1: INV. SEM 4 | K1: INVEN INIC SEM | N1: LAM | O1: CONTROL PRODUCCION SEMANA 21 - 2026 | Q1: CANT PROGRAMADA | R1: LUNES | S1: MARTES | T1: MIÉRCOLES | U1: JUEVES | V1: VIERNES | W1: SÁBADO | X1: DOMINGO | Y1: TOTAL SEMANA | AB1: TAPA | AD1: LAMINA | AE1: REFERENCIA LAMINA
A2: 306780 | B2: LAMINA CROM | C2: ='MODELO LAYOUT'!B54 -> 141 | D2: ='MODELO LAYOUT'!F54 -> 0 | E2: ='MODELO LAYOUT'!D54 -> 126 | F2: =C3 -> 267 | K2: =(C3)-G3 -> 267 | N2: MATERIAL | O2: MATERIAL | P2: DESCRIPCIÓN | Q2: TOTAL | R2: 46160 | S2: 46161 | T2: 46162 | U2: 46163 | V2: 46164 | W2: 46165 | X2: 46166 | Y2: UN | AB2: 207189 | AC2: TAPA AGUILA ORIGINAL GENERICA | AD2: 210760 | AE2: LAMINA AGUILA AZUL TIPO D 0.195
C3: =SUM(C2:E2) -> 267 | N3: =IFERROR(VLOOKUP(O3,$AB$2:$AE$80,3,0)," ") -> 212315 | O3: 202732 | P3: =IFERROR(_xlfn.CONCAT(VLOOKUP(O3,[1]CODIGOS!$A$1:$D$750,2,0)," ",O3," ","LINEA ",N3,)," ") -> TAPA COSTEÑITA RET CBARRAS LG 202732 LINEA 212315 | R3: 3663000 | U3: =225*11000 -> 2475000 | V3: =120*11000 -> 1320000 | Y3: =SUM(U3:X3) -> 3795000 | AB3: 207371 | AC3: TAPA AGUILA LIGHT R GENERICA | AD3: 211393 | AE3: LAMINA AGUILA LIGHT TIPO D 0.195 330
A4: CODIGO | B4: INVENTARIO DE LAMINA TERMINADA | C4: COD TAPA | D4: NUMERO LAM | E4: NUMERO PAQ | F4: CONSUMO SEM | G4: (FABRICACION) | H4: PROCESO | K4: INV. INICIAL | L4: CONSUMO REAL | N4: =IFERROR(VLOOKUP(O4,$AB$2:$AE$80,3,0)," ") -> 213995 | O4: 213994 | P4: =IFERROR(_xlfn.CONCAT(VLOOKUP(O4,[1]CODIGOS!$A$1:$D$750,2,0)," ",O4," ","LINEA ",N4,)," ") -> TAPA AGUILA MF 2026 213994 LINEA 213995 | R4: 2376000 | S4: 5907000 | W4: =129*11000 -> 1419000 | X4: =175*11000 -> 1925000 | Y4: =SUM(U4:X4) -> 3344000 | AB4: 211878 | AC4: TAPA AGUILA LIGHT 330 R CI PRECIO 2200 | AD4: 211863 | AE4: LAMINA ÁGUILA LIGHT 330 PS TIPO D 0.195
A5: 210760 | B5: =VLOOKUP(A5,$AD$1:$AE$89,2,0) -> LAMINA AGUILA AZUL TIPO D 0.195 | C5: 207189 | D5: =SUMIF(DATA!$A:$A,$A5,DATA!$B:$B)-SUMIFS(DATA!$B:$B,DATA!$A:$A,$A5,DATA!$E:$E,$L$1)-3760 -> 1165 | E5: =D5/1690 -> 0.68934911 | F5: =+L5/667/1690 -> 0 | K5: =(E5+G5)-F5 -> 0.68934911 | L5: =IFERROR(SUMIF($N$3:$N$38,A5,$Y$3:$Y$39)," ") -> 0 | N5: =IFERROR(VLOOKUP(O5,$AB$2:$AE$80,3,0)," ") -> 212694 | O5: 212703 | P5: =IFERROR(_xlfn.CONCAT(VLOOKUP(O5,[1]CODIGOS!$A$1:$D$750,2,0)," ",O5," ","LINEA ",N5,)," ") -> TAPA CLUB COL TRIGO 330 R 212703 LINEA 212694 | S5: 484000 | T5: 536431 | Y5: =SUM(U5:X5) -> 0 | AB5: 208472 | AC5: TAPA POKER 330R CI | AD5: 210761 | AE5: LAMINA POKER ROJA TIPO D 0.195
A6: 211393 | B6: =VLOOKUP(A6,$AD$1:$AE$89,2,0) -> LAMINA AGUILA LIGHT TIPO D 0.195 330 | C6: 207371 | D6: =SUMIF(DATA!$A:$A,$A6,DATA!$B:$B)-SUMIFS(DATA!$B:$B,DATA!$A:$A,$A6,DATA!$E:$E,$L$1) -> 0 | E6: =D6/1690 -> 0 | F6: =+L6/667/1690 -> 0 | K6: =(E6+G6)-F6 -> 0 | L6: =IFERROR(SUMIF($N$3:$N$38,A6,$Y$3:$Y$39)," ") -> 0 | N6: =IFERROR(VLOOKUP(O6,$AB$2:$AE$80,3,0)," ") -> 213868 | O6: 213867 | P6: =IFERROR(_xlfn.CONCAT(VLOOKUP(O6,[1]CODIGOS!$A$1:$D$750,2,0)," ",O6," ","LINEA ",N6,)," ") -> TAPA TEST 213867 LINEA 213868 | T6: 5709000 | U6: =2255000+935000 -> 3190000 | Y6: =SUM(U6:X6) -> 3190000 | AB6: 212407 | AC6: TAPA PRY OFF CLOVER 320 CC PRECIO 2000 | AD6: 212403 | AE6: LAMINA COSTEÑA BACANA 2000 TP D 0.195
A7: 211863 | B7: =VLOOKUP(A7,$AD$1:$AE$89,2,0) -> LAMINA ÁGUILA LIGHT 330 PS TIPO D 0.195 | C7: 211878 | D7: =SUMIF(DATA!$A:$A,$A7,DATA!$B:$B)-SUMIFS(DATA!$B:$B,DATA!$A:$A,$A7,DATA!$E:$E,$L$1) -> 0 | E7: =D7/1690 -> 0 | F7: =+L7/667/1690 -> 0 | K7: =(E7+G7)-F7 -> 0 | L7: =IFERROR(SUMIF($N$3:$N$38,A7,$Y$3:$Y$39)," ") -> 0 | N7: =IFERROR(VLOOKUP(O7,$AB$2:$AE$80,3,0)," ") -> 213367 | O7: 213361 | P7: =IFERROR(_xlfn.CONCAT(VLOOKUP(O7,[1]CODIGOS!$A$1:$D$750,2,0)," ",O7," ","LINEA ",N7,)," ") -> TAPA CLUB PREMIUM TW ECUADOR 213361 LINEA 213367 | V7: =409*11000 -> 4499000 | W7: =390*11000 -> 4290000 | Y7: =SUM(U7:X7) -> 8789000 | AB7: 211311 | AC7: TAPA NATIVA 330 | AD7: 211691 | AE7: LAMINA NATIVA SUR TIPO D 0.195
A8: 210761 | B8: =VLOOKUP(A8,$AD$1:$AE$89,2,0) -> LAMINA POKER ROJA TIPO D 0.195 | C8: 208472 | D8: =SUMIF(DATA!$A:$A,$A8,DATA!$B:$B)-SUMIFS(DATA!$B:$B,DATA!$A:$A,$A8,DATA!$E:$E,$L$1) -> 886 | E8: =D8/1690 -> 0.52426036 | F8: =+L8/667/1690 -> 0 | K8: =(E8+G8)-F8 -> 0.52426036 | L8: =IFERROR(SUMIF($N$3:$N$38,A8,$Y$3:$Y$39)," ") -> 0 | N8: =IFERROR(VLOOKUP(O8,$AB$2:$AE$80,3,0)," ") -> 213738 | O8: 213735 | P8: =IFERROR(_xlfn.CONCAT(VLOOKUP(O8,[1]CODIGOS!$A$1:$D$750,2,0)," ",O8," ","LINEA ",N8,)," ") -> TAPA RENOVATION POKER 213735 LINEA 213738 | R8: 5027000 | Y8: =SUM(U8:X8) -> 0 | AB8: 208078 | AC8: TAPA COLA & POLA ND LG IMG | AD8: 211672 | AE8: LAMINA COLA & POLA TIPO D 0.195
A9: 211208 | B9: =VLOOKUP(A9,$AD$1:$AE$89,2,0) -> LAMINA PILSEN GENERICA TIP D 0.195 | C9: 211824 | D9: =SUMIF(DATA!$A:$A,$A9,DATA!$B:$B)-SUMIFS(DATA!$B:$B,DATA!$A:$A,$A9,DATA!$E:$E,$L$1) -> 15323 | E9: =D9/1690 -> 9.0668639 | F9: =+L9/667/1690 -> 0 | K9: =(E9+G9)-F9 -> 9.0668639 | L9: =IFERROR(SUMIF($N$3:$N$38,A9,$Y$3:$Y$39)," ") -> 0 | N9: =IFERROR(VLOOKUP(O9,$AB$2:$AE$80,3,0)," ") -> 212315 | O9: 202732 | P9: =IFERROR(_xlfn.CONCAT(VLOOKUP(O9,[1]CODIGOS!$A$1:$D$750,2,0)," ",O9," ","LINEA ",N9,)," ") -> TAPA COSTEÑITA RET CBARRAS LG 202732 LINEA 212315 | W9: =427*11000 -> 4697000 | X9: =172*11000 -> 1892000 | Y9: =SUM(U9:X9) -> 6589000 | AB9: 209630 | AC9: TAPA EVENTO YO ME CUIDO PERU | AD9: 211305 | AE9: LAMINA YO ME CUIDO PERU TIPO D 0.195
A10: 212403 | B10: =VLOOKUP(A10,$AD$1:$AE$89,2,0) -> LAMINA COSTEÑA BACANA 2000 TP D 0.195 | C10: 212407 | D10: =SUMIF(DATA!$A:$A,$A10,DATA!$B:$B)-SUMIFS(DATA!$B:$B,DATA!$A:$A,$A10,DATA!$E:$E,$L$1) -> 6497 | E10: =D10/1690 -> 3.8443787 | F10: =+L10/667/1690 -> 0.42937111 | K10: =(E10+G10)-F10 -> 3.4150076 | L10: =IFERROR(SUMIF($N$3:$N$38,A10,$Y$3:$Y$39)," ") -> 484000 | N10: =IFERROR(VLOOKUP(O10,$AB$2:$AE$80,3,0)," ") -> 213995 | O10: 213994 | P10: =IFERROR(_xlfn.CONCAT(VLOOKUP(O10,[1]CODIGOS!$A$1:$D$750,2,0)," ",O10," ","LINEA ",N10,)," ") -> TAPA AGUILA MF 2026 213994 LINEA 213995 | U10: =98*11000 -> 1078000 | V10: =532*11000 -> 5852000 | W10: =111*11000 -> 1221000 | Y10: =SUM(U10:X10) -> 8151000 | AB10: 212195 | AC10: TAPA YO ME CUIDO PERU ST | AD10: 212127 | AE10: LAMINA YO ME CUIDO PERU ST TIPO D 0.195
A11: 211691 | B11: =VLOOKUP(A11,$AD$1:$AE$89,2,0) -> LAMINA NATIVA SUR TIPO D 0.195 | C11: 211452 | D11: =SUMIF(DATA!$A:$A,$A11,DATA!$B:$B)-SUMIFS(DATA!$B:$B,DATA!$A:$A,$A11,DATA!$E:$E,$L$1) -> 1847 | E11: =D11/1690 -> 1.0928994 | F11: =+L11/667/1690 -> 0 | K11: =(E11+G11)-F11 -> 1.0928994 | L11: =IFERROR(SUMIF($N$3:$N$38,A11,$Y$3:$Y$39)," ") -> 0 | N11: =IFERROR(VLOOKUP(O11,$AB$2:$AE$80,3,0)," ") -> 213637 | O11: 213635 | P11: =IFERROR(_xlfn.CONCAT(VLOOKUP(O11,[1]CODIGOS!$A$1:$D$750,2,0)," ",O11," ","LINEA ",N10,)," ") -> TAPA AGUILA LIGHT PROMO ALFA 213635 LINEA 213995 | R11: 979000 | S11: 4499000 | T11: =440*11000 -> 4840000 | U11: =428*11000 -> 4708000 | Y11: =SUM(U11:X11) -> 4708000 | AB11: 209629 | AC11: TAPA GOLDEN PERU | AD11: 212481 | AE11: LAMINA GOLDEN TIPO D 0.195
A12: 213802 | B12: =VLOOKUP(A12,$AD$1:$AE$89,2,0) -> LAMINA MCHELOB ULTRA NRB 330 TIPO D0.195 | C12: 213801 | D12: =SUMIF(DATA!$A:$A,$A12,DATA!$B:$B)-SUMIFS(DATA!$B:$B,DATA!$A:$A,$A12,DATA!$E:$E,$L$1) -> 0 | E12: =D12/1690 -> 0 | F12: =+L12/667/1690 -> 0 | K12: =(E12+G12)-F12 -> 0 | L12: =IFERROR(SUMIF($N$3:$N$38,A12,$Y$3:$Y$39)," ") -> 0 | N12: =IFERROR(VLOOKUP(O12,$AB$2:$AE$80,3,0)," ") -> 213995 | O12: 213994 | P12: =IFERROR(_xlfn.CONCAT(VLOOKUP(O12,[1]CODIGOS!$A$1:$D$750,2,0)," ",O12," ","LINEA ",N11,)," ") -> TAPA AGUILA MF 2026 213994 LINEA 213637 | S12: 2453000 | T12: =(254*11000)+6550 -> 2800550 | Y12: =SUM(U12:X12) -> 0 | AB12: 209631 | AC12: TAPA CUSQUEÑA CALIDAD PERU | AD12: 211306 | AE12: LAMINA CUSQUEÑA CALIDAD TIPO D 0.195
A13: 212066 | B13: =VLOOKUP(A13,$AD$1:$AE$89,2,0) -> LAMINA CC ROJA TIPO D 0.195 NEW VBI | C13: 212013 | D13: =SUMIF(DATA!$A:$A,$A13,DATA!$B:$B)-SUMIFS(DATA!$B:$B,DATA!$A:$A,$A13,DATA!$E:$E,$L$1) -> 0 | E13: =D13/1690 -> 0 | F13: =+L13/667/1690 -> 0 | K13: =(E13+G13)-F13 -> 0 | L13: =IFERROR(SUMIF($N$3:$N$38,A13,$Y$3:$Y$39)," ") -> 0 | N13: =IFERROR(VLOOKUP(O13,$AB$2:$AE$80,3,0)," ") -> 212019 | O13: 212016 | P13: =IFERROR(_xlfn.CONCAT(VLOOKUP(O13,[1]CODIGOS!$A$1:$D$750,2,0)," ",O13," ","LINEA ",N12,)," ") -> TAPA CLUB COL DRDA R NEW VBI 212016 LINEA 213995 | T13: 121000 | U13: =531*11000 -> 5841000 | V13: =250*11000 -> 2750000 | Y13: =SUM(U13:X13) -> 8591000 | AB13: 212013 | AC13: TAPA CLUB COL ROJA R NEW VBI | AD13: 212066 | AE13: LAMINA CC ROJA TIPO D 0.195 NEW VBI
A14: 212068 | B14: =VLOOKUP(A14,$AD$1:$AE$89,2,0) -> LAMINA CC NEGRA TIPO D 0.195 NEW VBI | C14: 212014 | D14: =SUMIF(DATA!$A:$A,$A14,DATA!$B:$B)-SUMIFS(DATA!$B:$B,DATA!$A:$A,$A14,DATA!$E:$E,$L$1) -> 0 | E14: =D14/1690 -> 0 | F14: =+L14/667/1690 -> 0 | K14: =(E14+G14)-F14 -> 0 | L14: =IFERROR(SUMIF($N$3:$N$38,A14,$Y$3:$Y$39)," ") -> 0 | N14: =IFERROR(VLOOKUP(O14,$AB$2:$AE$80,3,0)," ") -> 213738 | O14: 213735 | P14: =IFERROR(_xlfn.CONCAT(VLOOKUP(O14,[1]CODIGOS!$A$1:$D$750,2,0)," ",O14," ","LINEA ",N13,)," ") -> TAPA RENOVATION POKER 213735 LINEA 212019 | R14: 5962000 | S14: 3729000 | V14: =279*11000 -> 3069000 | W14: =557*11000 -> 6127000 | X14: =167*11000 -> 1837000 | Y14: =SUM(U14:X14) -> 11033000 | AB14: 212014 | AC14: TAPA CLUB COL NG R NEW VBI | AD14: 212068 | AE14: LAMINA CC NEGRA TIPO D 0.195 NEW VBI
A15: 212019 | B15: =VLOOKUP(A15,$AD$1:$AE$89,2,0) -> LAMINA TIPO D 0.195 CLUB COLOM NEW VBI | C15: 212016 | D15: =SUMIF(DATA!$A:$A,$A15,DATA!$B:$B)-SUMIFS(DATA!$B:$B,DATA!$A:$A,$A15,DATA!$E:$E,$L$1) -> 1349 | E15: =D15/1690 -> 0.79822485 | F15: =+L15/667/1690 -> 7.6213373 | K15: =(E15+G15)-F15 -> -6.8231124 | L15: =IFERROR(SUMIF($N$3:$N$38,A15,$Y$3:$Y$39)," ") -> 8591000 | N15: =IFERROR(VLOOKUP(O15,$AB$2:$AE$80,3,0)," ") -> 212315 | O15: 202732 | P15: =IFERROR(_xlfn.CONCAT(VLOOKUP(O15,[1]CODIGOS!$A$1:$D$750,2,0)," ",O15," ","LINEA ",N14,)," ") -> TAPA COSTEÑITA RET CBARRAS LG 202732 LINEA 213738 | T15: 3025000 | Y15: =SUM(U15:X15) -> 0 | AB15: 212016 | AC15: TAPA CLUB COL DRDA R NEW VBI | AD15: 212019 | AE15: LAMINA TIPO D 0.195 CLUB COLOM NEW VBI
A16: 212378 | B16: =VLOOKUP(A16,$AD$1:$AE$89,2,0) -> LAMINA CC OKTOBERFEST TIPOD 0.195 | C16: 212265 | D16: =SUMIF(DATA!$A:$A,$A16,DATA!$B:$B)-SUMIFS(DATA!$B:$B,DATA!$A:$A,$A16,DATA!$E:$E,$L$1) -> 0 | E16: =D16/1690 -> 0 | F16: =+L16/667/1690 -> 0 | K16: =(E16+G16)-F16 -> 0 | L16: =IFERROR(SUMIF($N$3:$N$38,A16,$Y$3:$Y$39)," ") -> 0 | N16: =IFERROR(VLOOKUP(O16,$AB$2:$AE$80,3,0)," ") -> 212403 | O16: 212407 | P16: =IFERROR(_xlfn.CONCAT(VLOOKUP(O16,[1]CODIGOS!$A$1:$D$750,2,0)," ",O16," ","LINEA ",N15,)," ") -> TAPA PRY OFF CLOVER 320 CC PRECIO 2000 212407 LINEA 212315 | R16: 286000 | S16: 7458000 | T16: =651*11000 -> 7161000 | U16: 484000 | Y16: =SUM(U16:X16) -> 484000 | AB16: 212265 | AC16: TAPA CLUB COL DOBLE MALTA 330R FEST | AD16: 212378 | AE16: LAMINA CC OKTOBERFEST TIPOD 0.195
A17: 211217 | B17: =VLOOKUP(A17,$AD$1:$AE$89,2,0) -> LAMINA BUDWEISER TW TIPO D 0.195 | C17: 212080 | D17: =SUMIF(DATA!$A:$A,$A17,DATA!$B:$B)-SUMIFS(DATA!$B:$B,DATA!$A:$A,$A17,DATA!$E:$E,$L$1) -> 1728 | E17: =D17/1690 -> 1.0224852 | F17: =+L17/667/1690 -> 0 | K17: =(E17+G17)-F17 -> 1.0224852 | L17: =IFERROR(SUMIF($N$3:$N$38,A17,$Y$3:$Y$39)," ") -> 0 | N17: =IFERROR(VLOOKUP(O17,$AB$2:$AE$80,3,0)," ") -> 212127 | O17: 212195 | P17: =IFERROR(_xlfn.CONCAT(VLOOKUP(O17,[1]CODIGOS!$A$1:$D$750,2,0)," ",O17," ","LINEA ",N16,)," ") -> TAPA YO ME CUIDO PERU ST 212195 LINEA 212403 | U17: =1089000+781000+1000000 -> 2870000 | V17: =640*11000 -> 7040000 | W17: =150*11000 -> 1650000 | Y17: =SUM(U17:X17) -> 11560000 | AB17: 212080 | AC17: TAPA BUDWEISER RB PRY OFF 250CC | AD17: 211217 | AE17: LAMINA BUDWEISER TW TIPO D 0.195
A18: 211216 | B18: =VLOOKUP(A18,$AD$1:$AE$89,2,0) -> LAMINA PONY ROJA CI TIPO D 0.195 | C18: 208453 | D18: =SUMIF(DATA!$A:$A,$A18,DATA!$B:$B)-SUMIFS(DATA!$B:$B,DATA!$A:$A,$A18,DATA!$E:$E,$L$1) -> 0 | E18: =D18/1690 -> 0 | F18: =+L18/667/1690 -> 0 | K18: =(E18+G18)-F18 -> 0 | L18: =IFERROR(SUMIF($N$3:$N$38,A18,$Y$3:$Y$39)," ") -> 0 | N18: =IFERROR(VLOOKUP(O18,$AB$2:$AE$80,3,0)," ") -> 211209 | O18: 208749 | P18: =IFERROR(_xlfn.CONCAT(VLOOKUP(O18,[1]CODIGOS!$A$1:$D$750,2,0)," ",O18," ","LINEA ",N17,)," ") -> TAPA CORONA 355 MONOLABIAL 208749 LINEA 212127 | R18: 6345249 | Y18: =SUM(U18:X18) -> 0 | AB18: 208453 | AC18: TAPA PONY MALTA GENERICA N CI | AD18: 211216 | AE18: LAMINA PONY ROJA CI TIPO D 0.195
A19: 212315 | B19: =VLOOKUP(A19,$AD$1:$AE$89,2,0) -> LAMINA COSTEÑITA CBARRAS LG TIPOD.0.195 | C19: 202732 | D19: =SUMIF(DATA!$A:$A,$A19,DATA!$B:$B)-SUMIFS(DATA!$B:$B,DATA!$A:$A,$A19,DATA!$E:$E,$L$1) -> 16722 | E19: =D19/1690 -> 9.8946746 | F19: =+L19/667/1690 -> 9.2119621 | G19: 9 | K19: =(E19+G19)-F19 -> 9.6827125 | L19: =IFERROR(SUMIF($N$3:$N$38,A19,$Y$3:$Y$39)," ") -> 10384000 | N19: =IFERROR(VLOOKUP(O19,$AB$2:$AE$80,3,0)," ") -> 213995 | O19: 213994 | P19: =IFERROR(_xlfn.CONCAT(VLOOKUP(O19,[1]CODIGOS!$A$1:$D$750,2,0)," ",O19," ","LINEA ",N18,)," ") -> TAPA AGUILA MF 2026 213994 LINEA 211209 | W19: =500*11000 -> 5500000 | X19: =241*11000 -> 2651000 | Y19: =SUM(U19:X19) -> 8151000 | AB19: 202732 | AC19: TAPA COSTEÑITA RET CBARRAS LG | AD19: 212315 | AE19: LAMINA COSTEÑITA CBARRAS LG TIPOD.0.195
A20: 212604 | B20: =VLOOKUP(A20,$AD$1:$AE$89,2,0) -> LAMINA COSTEÑA ROJA TIPO D0.195 | C20: 212601 | D20: =SUMIF(DATA!$A:$A,$A20,DATA!$B:$B)-SUMIFS(DATA!$B:$B,DATA!$A:$A,$A20,DATA!$E:$E,$L$1) -> 2413 | E20: =D20/1690 -> 1.4278107 | F20: =+L20/667/1690 -> 0 | K20: =(E20+G20)-F20 -> 1.4278107 | L20: =IFERROR(SUMIF($N$3:$N$38,A20,$Y$3:$Y$39)," ") -> 0 | Q20: =SUM(Q3:Q19) -> 0 | R20: =SUBTOTAL(9,R3:R19) -> 24638249 | S20: =SUBTOTAL(9,S3:S19) -> 24530000 | T20: =SUBTOTAL(9,T3:T19) -> 24192981 | U20: =SUBTOTAL(9,U3:U19) -> 20646000 | V20: =SUBTOTAL(9,V3:V19) -> 24530000 | W20: =SUBTOTAL(9,W3:W19) -> 24904000 | X20: =SUBTOTAL(9,X3:X19) -> 8305000 | Y20: =+R20+S20+T20+U20+V20+W20+X20 -> 151746230 | AB20: 212601 | AC20: TAPA COSTEÑA 330R/750R | AD20: 212604 | AE20: LAMINA COSTEÑA ROJA TIPO D0.195
A21: 211209 | B21: =VLOOKUP(A21,$AD$1:$AE$89,2,0) -> LAMINA CORONA MARTE TIPO D 0.195 | C21: 208479 | D21: =SUMIF(DATA!$A:$A,$A21,DATA!$B:$B)-SUMIFS(DATA!$B:$B,DATA!$A:$A,$A21,DATA!$E:$E,$L$1) -> 3061 | E21: =D21/1690 -> 1.8112426 | F21: =+L21/667/1690 -> 0 | K21: =(E21+G21)-F21 -> 1.8112426 | L21: =IFERROR(SUMIF($N$3:$N$38,A21,$Y$3:$Y$39)," ") -> 0 | N21: =IFERROR(VLOOKUP(O23,$AB$2:$AE$80,3,0)," ") | AB21: 208749 | AC21: TAPA CORONA 355 MONOLABIAL | AD21: 211209 | AE21: LAMINA CORONA MARTE TIPO D 0.195
A22: 212321 | B22: =VLOOKUP(A22,$AD$1:$AE$89,2,0) -> LAMINA BBC LG TIPOD.0.195 | C22: 206051 | D22: =SUMIF(DATA!$A:$A,$A22,DATA!$B:$B)-SUMIFS(DATA!$B:$B,DATA!$A:$A,$A22,DATA!$E:$E,$L$1) -> 0 | E22: =D22/1690 -> 0 | F22: =+L22/667/1690 -> 0 | K22: =(E22+G22)-F22 -> 0 | L22: =IFERROR(SUMIF($N$3:$N$38,A22,$Y$3:$Y$39)," ") -> 0 | N22: =IFERROR(VLOOKUP(O24,$AB$2:$AE$80,3,0)," ") | AB22: 206051 | AC22: TAPA BBC LG | AD22: 212321 | AE22: LAMINA BBC LG TIPOD.0.195
A23: 212694 | B23: =VLOOKUP(A23,$AD$1:$AE$89,2,0) -> LAMINA CLUB COLOMBIA TRIGO TIPO D0.195 | C23: 212703 | D23: =SUMIF(DATA!$A:$A,$A23,DATA!$B:$B)-SUMIFS(DATA!$B:$B,DATA!$A:$A,$A23,DATA!$E:$E,$L$1) -> 0 | E23: =D23/1690 -> 0 | F23: =+L23/667/1690 -> 0 | K23: =(E23+G23)-F23 -> 0 | L23: =IFERROR(SUMIF($N$3:$N$38,A23,$Y$3:$Y$39)," ") -> 0 | N23: =IFERROR(VLOOKUP(O25,$AB$2:$AE$80,3,0)," ") | AB23: 212738 | AC23: TAPA AGUILA ORIGINAL NRB | AD23: 212751 | AE23: LAMINA AGUILA ORIGINAL NV TIPO D0.195
A24: 212787 | B24: =VLOOKUP(A24,$AD$1:$AE$89,2,0) -> LAMINA CORONA CERO TIPO D 0,195 | C24: 212812 | D24: =SUMIF(DATA!$A:$A,$A24,DATA!$B:$B)-SUMIFS(DATA!$B:$B,DATA!$A:$A,$A24,DATA!$E:$E,$L$1) -> 1629 | E24: =D24/1690 -> 0.96390533 | F24: =+L24/667/1690 -> 0 | K24: =(E24+G24)-F24 -> 0.96390533 | L24: =IFERROR(SUMIF($N$3:$N$38,A24,$Y$3:$Y$39)," ") -> 0 | N24: =IFERROR(VLOOKUP(O26,$AB$2:$AE$80,3,0)," ") | AB24: 212814 | AC24: TAPA CORONA OLIMPICS | AD24: 212797 | AE24: LAMINA CORONA OLIMPICOS TIPO D 0.195
A25: 213343 | B25: =VLOOKUP(A25,$AD$1:$AE$89,2,0) -> LAMINA AGUILA EL CARIBE D 0.195 | C25: 213340 | D25: =SUMIF(DATA!$A:$A,$A25,DATA!$B:$B)-SUMIFS(DATA!$B:$B,DATA!$A:$A,$A25,DATA!$E:$E,$L$1) -> 629 | E25: =D25/1690 -> 0.37218935 | F25: =+L25/667/1690 -> 0 | K25: =(E25+G25)-F25 -> 0.37218935 | L25: =IFERROR(SUMIF($N$3:$N$38,A25,$Y$3:$Y$39)," ") -> 0 | N25: =IFERROR(VLOOKUP(O27,$AB$2:$AE$80,3,0)," ") | AB25: 212739 | AC25: TAPA AGUILA LIGHT NRB | AD25: 212749 | AE25: LAMINA AGUILA LIGHT NV TIPO D0.195
A26: 213354 | B26: =VLOOKUP(A26,$AD$1:$AE$89,2,0) -> LAMINA REDDS CITRUS UV 0.195 | C26: 213328 | D26: =SUMIF(DATA!$A:$A,$A26,DATA!$B:$B)-SUMIFS(DATA!$B:$B,DATA!$A:$A,$A26,DATA!$E:$E,$L$1) -> 0 | E26: =D26/1690 -> 0 | F26: =+L26/667/1690 -> 0 | K26: =(E26+G26)-F26 -> 0 | L26: =IFERROR(SUMIF($N$3:$N$38,A26,$Y$3:$Y$39)," ") -> 0 | N26: =IFERROR(VLOOKUP(O28,$AB$2:$AE$80,3,0)," ") | Q26: CUSQUEÑA | R26: 3800000 | AB26: 212703 | AC26: TAPA CLUB COL TRIGO 330 R | AD26: 212694 | AE26: LAMINA CLUB COLOMBIA TRIGO TIPO D0.195
A27: 213415 | B27: =VLOOKUP(A27,$AD$1:$AE$89,2,0) -> LAMINA AGUILA GOLES UV TIPO D0.195 | C27: 213413 | D27: =SUMIF(DATA!$A:$A,$A27,DATA!$B:$B)-SUMIFS(DATA!$B:$B,DATA!$A:$A,$A27,DATA!$E:$E,$L$1) -> 0 | E27: =D27/1690 -> 0 | F27: =+L27/667/1690 -> 0 | K27: =(E27+G27)-F27 -> 0 | L27: =IFERROR(SUMIF($N$3:$N$38,A27,$Y$3:$Y$39)," ") -> 0 | N27: =IFERROR(VLOOKUP(O29,$AB$2:$AE$80,3,0)," ") | Q27: YO ME CUIDO | R27: 23900000 | AB27: 212916 | AC27: TAPA AGUILA COPA AMERICA | AD27: 212917 | AE27: LAMINA AGUILA COPA AMERICA TIPO D0.195
A28: 213438 | B28: =VLOOKUP(A28,$AD$1:$AE$89,2,0) -> LAMINA COLA & POLA UV TIPO D0.195 | C28: 213420 | D28: =SUMIF(DATA!$A:$A,$A28,DATA!$B:$B)-SUMIFS(DATA!$B:$B,DATA!$A:$A,$A28,DATA!$E:$E,$L$1) -> 0 | E28: =D28/1690 -> 0 | F28: =+L28/667/1690 -> 0 | K28: =(E28+G28)-F28 -> 0 | L28: =IFERROR(SUMIF($N$3:$N$38,A28,$Y$3:$Y$39)," ") -> 0 | AB28: 213208 | AC28: TAPA TOUR AGUILA 330 | AD28: 213210 | AE28: LAMINA UV TOUR AGUILA TIPO D0.195
A29: 213352 | B29: =VLOOKUP(A29,$AD$1:$AE$89,2,0) -> LAMINA NUTRI MALTA D 0.195 | C29: 213341 | D29: =SUMIF(DATA!$A:$A,$A29,DATA!$B:$B)-SUMIFS(DATA!$B:$B,DATA!$A:$A,$A29,DATA!$E:$E,$L$1) -> 1519 | E29: =D29/1690 -> 0.89881657 | F29: =+L29/667/1690 -> 0 | K29: =(E29+G29)-F29 -> 0.89881657 | L29: =IFERROR(SUMIF($N$3:$N$38,A29,$Y$3:$Y$39)," ") -> 0 | AB29: 213208 | AC29: TAPA TOUR AGUILA 330 | AD29: 213209 | AE29: LAMINA COV TOUR AGUILA TIPO D0.195
A30: 213324 | B30: =VLOOKUP(A30,$AD$1:$AE$89,2,0) -> LAMINA PONY MALTA GO 0.195 | C30: 213321 | D30: =SUMIF(DATA!$A:$A,$A30,DATA!$B:$B)-SUMIFS(DATA!$B:$B,DATA!$A:$A,$A30,DATA!$E:$E,$L$1) -> 0 | E30: =D30/1690 -> 0 | F30: =+L30/667/1690 -> 0 | K30: =(E30+G30)-F30 -> 0 | L30: =IFERROR(SUMIF($N$3:$N$38,A30,$Y$3:$Y$39)," ") -> 0 | AB30: 213146 | AC30: TAPA AGUILA IMPERIAL 330 R | AD30: 213147 | AE30: LAMINA AGUILA IMPERIAL TIPO D0.195
A31: 213482 | B31: =VLOOKUP(A31,$AD$1:$AE$89,2,0) -> LAMINA PILSEN FRASES TIPO D0.195 | C31: 213481 | D31: =SUMIF(DATA!$A:$A,$A31,DATA!$B:$B)-SUMIFS(DATA!$B:$B,DATA!$A:$A,$A31,DATA!$E:$E,$L$1) -> 0 | E31: =D31/1690 -> 0 | F31: =+L31/667/1690 -> 0 | K31: =(E31+G31)-F31 -> 0 | L31: =IFERROR(SUMIF($N$3:$N$38,A31,$Y$3:$Y$39)," ") -> 0 | Q31: 19 YO ME CUIDO | AB31: 212812 | AC31: TAPA CORONA CERO MX | AD31: 212787 | AE31: LAMINA CORONA CERO TIPO D 0,195
A32: 213325 | B32: =VLOOKUP(A32,$AD$1:$AE$89,2,0) -> LAMINA PONY MALTA ANTOJOS 0.195 | C32: 213322 | D32: =SUMIF(DATA!$A:$A,$A32,DATA!$B:$B)-SUMIFS(DATA!$B:$B,DATA!$A:$A,$A32,DATA!$E:$E,$L$1) -> 0 | E32: =D32/1690 -> 0 | F32: =+L32/667/1690 -> 0 | K32: =(E32+G32)-F32 -> 0 | L32: =IFERROR(SUMIF($N$3:$N$38,A32,$Y$3:$Y$39)," ") -> 0 | Q32: 17 CUSQUEÑA | AB32: 213229 | AC32: TAPA COSTEÑA LA VIDA BACANA | AD32: 213237 | AE32: LAMINA COSTEÑA LA VIDA BACANA
A33: 213637 | B33: =VLOOKUP(A33,$AD$1:$AE$89,2,0) -> LAMINA AGUILA LGT PROMO ALFA TIP D 0.195 | C33: 213635 | D33: =SUMIF(DATA!$A:$A,$A33,DATA!$B:$B)-SUMIFS(DATA!$B:$B,DATA!$A:$A,$A33,DATA!$E:$E,$L$1) -> 25460 | E33: =D33/1690 -> 15.065089 | F33: =+L33/667/1690 -> 4.1766099 | K33: =(E33+G33)-F33 -> 10.888479 | L33: =IFERROR(SUMIF($N$3:$N$38,A33,$Y$3:$Y$39)," ") -> 4708000 | AB33: 213340 | AC33: TAPA AGUILA EL CARIBE | AD33: 213356 | AE33: LAMINA AGUILA CARIBE
A34: 213738 | B34: =VLOOKUP(A34,$AD$1:$AE$89,2,0) -> LAMINA POKER RENOVACION | C34: 213735 | D34: =SUMIF(DATA!$A:$A,$A34,DATA!$B:$B)-SUMIFS(DATA!$B:$B,DATA!$A:$A,$A34,DATA!$E:$E,$L$1)-2938 -> 7188 | E34: =D34/1690 -> 4.2532544 | F34: =+L34/667/1690 -> 9.7877097 | G34: 20 | K34: =(E34+G34)-F34 -> 14.465545 | L34: =IFERROR(SUMIF($N$3:$N$38,A34,$Y$3:$Y$39)," ") -> 11033000 | AB34: 213340 | AC34: TAPA AGUILA EL CARIBE | AD34: 213343 | AE34: LAMINA AGUILA EL CARIBE D 0.195
A35: 213732 | B35: =VLOOKUP(A35,$AD$1:$AE$89,2,0) -> LAMINA COSTEÑA BACANA CENTRO TIPO D 0.195 | C35: 213731 | D35: =SUMIF(DATA!$A:$A,$A35,DATA!$B:$B)-SUMIFS(DATA!$B:$B,DATA!$A:$A,$A35,DATA!$E:$E,$L$1) -> 743 | E35: =D35/1690 -> 0.43964497 | F35: =+L35/667/1690 -> 0 | K35: =(E35+G35)-F35 -> 0.43964497 | L35: =IFERROR(SUMIF($N$3:$N$38,A35,$Y$3:$Y$39)," ") -> 0 | AB35: 213328 | AC35: TAPA REDDS CITRUS | AD35: 213354 | AE35: LAMINA REDDS CITRUS UV 0.195
A36: 213868 | B36: =VLOOKUP(A36,$AD$1:$AE$89,2,0) -> LAMINA TAPA TEST CONV TIPO D0.195 | C36: 213867 | D36: =SUMIF(DATA!$A:$A,$A36,DATA!$B:$B)-SUMIFS(DATA!$B:$B,DATA!$A:$A,$A36,DATA!$E:$E,$L$1) -> 400 | E36: =D36/1690 -> 0.23668639 | F36: =+L36/667/1690 -> 2.829946 | K36: =(E36+G36)-F36 -> -2.5932596 | L36: =IFERROR(SUMIF($N$3:$N$38,A36,$Y$3:$Y$39)," ") -> 3190000 | AB36: 213413 | AC36: TAPA AGUILA GOLES | AD36: 213415 | AE36: LAMINA AGUILA GOLES UV TIPO D0.195
A37: 213869 | B37: =VLOOKUP(A37,$AD$1:$AE$89,2,0) -> LAMINA TAPA TEST UV TIPO D0.195 | C37: 213867 | D37: =SUMIF(DATA!$A:$A,$A37,DATA!$B:$B)-SUMIFS(DATA!$B:$B,DATA!$A:$A,$A37,DATA!$E:$E,$L$1) -> 0 | E37: =D37/1690 -> 0 | F37: =+L37/667/1690 -> 0 | K37: =(E37+G37)-F37 -> 0 | L37: =IFERROR(SUMIF($N$3:$N$38,A37,$Y$3:$Y$39)," ") -> 0 | AB37: 213304 | AC37: TAPA CLUB PREMIUM CLASICA | AD37: 213246 | AE37: LAMINA CLUB PREMIUM CLASICA TIPO D 0.195
A38: 211305 | B38: =VLOOKUP(A38,$AD$1:$AE$89,2,0) -> LAMINA YO ME CUIDO PERU TIPO D 0.195 | C38: 209630 | D38: =SUMIF(DATA!$A:$A,$A38,DATA!$B:$B)-SUMIFS(DATA!$B:$B,DATA!$A:$A,$A38,DATA!$E:$E,$L$1) -> 0 | E38: =D38/1690 -> 0 | F38: =+L38/667/1690 -> 0 | K38: =(E38+G38)-F38 -> 0 | L38: =IFERROR(SUMIF($N$3:$N$38,A38,$Y$3:$Y$39)," ") -> 0 | AB38: 213420 | AC38: TAPA COLA & POLA NUEVA IMAGEN | AD38: 213438 | AE38: LAMINA COLA & POLA UV TIPO D0.195
A39: 212127 | B39: =VLOOKUP(A39,$AD$1:$AE$89,2,0) -> LAMINA YO ME CUIDO PERU ST TIPO D 0.195 | C39: 212195 | D39: =SUMIF(DATA!$A:$A,$A39,DATA!$B:$B)-SUMIFS(DATA!$B:$B,DATA!$A:$A,$A39,DATA!$E:$E,$L$1) -> 2393 | E39: =D39/1690 -> 1.4159763 | F39: =+L39/667/1690 -> 10.255227 | K39: =(E39+G39)-F39 -> -8.8392511 | L39: =IFERROR(SUMIF($N$3:$N$38,A39,$Y$3:$Y$39)," ") -> 11560000 | AB39: 213341 | AC39: TAPA NUTRI MALTA | AD39: 213352 | AE39: LAMINA NUTRI MALTA D 0.195
A40: 212481 | B40: =VLOOKUP(A40,$AD$1:$AE$89,2,0) -> LAMINA GOLDEN TIPO D 0.195 | C40: 209629 | D40: =SUMIF(DATA!$A:$A,$A40,DATA!$B:$B)-SUMIFS(DATA!$B:$B,DATA!$A:$A,$A40,DATA!$E:$E,$L$1) -> 0 | E40: =D40/1690 -> 0 | F40: =+L40/667/1690 -> 0 | K40: =(E40+G40)-F40 -> 0 | L40: =IFERROR(SUMIF($N$3:$N$38,A40,$Y$3:$Y$39)," ") -> 0 | AB40: 213321 | AC40: TAPA PONY MALTA GO | AD40: 213324 | AE40: LAMINA PONY MALTA GO 0.195
...

Sheet MODELO LAYOUT
AE1: SALIDA DE MONTACARGAS | CI1: LAMINA | CJ1: TAPA | CK1: DESCRIPCION | CL1: CONSUMO | CM1: DESCRIPCION CONSUMO | CN1: CODIGO | CO1: CANTIDAD | CP1: =AI15 -> 0 | CQ1: =AJ15 -> 0 | CR1: =AK15 -> 0 | CS1: =AL15 -> 0 | CT1: =AM15 -> 0 | CU1: =AN15 -> 0 | CV1: =AO15 -> 0 | CW1: =AP15 -> 0 | ... DN1: =BG15 -> 0
CI2: 211749 | CJ2: N/A | CK2: LAM BASE BLANCA LACA OXY TIPO 0.195 | CL2: N/A | CM2: N/A | CN2: {=TRANSPOSE(CP1:EF1)} -> 0 | CO2: {=TRANSPOSE(CP2:EF2)} -> 0 | CP2: =AI14 -> 0 | CQ2: =AJ14 -> 0 | CR2: =AK14 -> 0 | CS2: =AL14 -> 0 | CT2: =AM14 -> 0 | CU2: =AN14 -> 0 | CV2: =AO14 -> 0 | CW2: =AP14 -> 0 | ... DN2: =BG14 -> 0
CI3: 211747 | CJ3: N/A | CK3: LAM SIZING ALUM LACA OXY TIPO D 0.195 | CL3: N/A | CM3: N/A | CN3: 0 | CO3: 0
A4: BAÑOS HOMBRES | D4: ALMACEN DE BASES Y RECUBRIMIENTOS BT04 | K4: ALMACEN DE BASES Y RECUBRIMIENTOS BT08 | S4: CUARTO DE GANCHOS | W4: CUARTO DE LUBRICANTES | AI4: CUARTO DE COMPRESORES | CI4: 210656 | CJ4: N/A | CK4: LAMINA GEN BASE BLANCA LACADA TIPO D 0.195 | CL4: N/A | CM4: N/A | CN4: 0 | CO4: 0 | CP4: =AI21 -> 0 | CQ4: =AJ21 -> 0 | CR4: =AK21 -> 0 | CS4: =AL21 -> 0 | CT4: =AM21 -> 0 | CU4: =AN21 -> 0 | CV4: =AO21 -> 0 | CW4: =AP21 -> 0 | ... DN4: =BG21 -> 0
AI5: BODEGA DE MOTORES | AM5: CUARTO DE PLANCHAS | AQ5: ALMACEN DE TINTAS | AU5: CENTRO DE CONFIABILIDAD | BH5: LABORATORIO | BR5: CENTRO DE ACOPIO 1 | BZ5: SALIDA EMERGENCIA | CI5: 212037 | CJ5: N/A | CK5: BASE DORADA LACADA 0.195 | CL5: N/A | CM5: N/A | CN5: 0 | CO5: 0 | CP5: =AI20 -> 0 | CQ5: =AJ20 -> 0 | CR5: =AK20 -> 0 | CS5: =AL20 -> 0 | CT5: =AM20 -> 0 | CU5: =AN20 -> 0 | CV5: =AO20 -> 0 | CW5: =AP20 -> 0 | ... DN5: =BG20 -> 0
A6: BAÑOS MUJERES | D6: ALMACEN DE REPUESTOS | P6: CUARTO DE RODILLOS | CI6: 212357 | CJ6: N/A | CK6: LAMINA LACADA BBC LG TIPO D0.195 | CL6: N/A | CM6: N/A | CN6: 0 | CO6: 0
CI7: 210654 | CJ7: N/A | CK7: LAMINA GEN LACADA TIPO D 0,195 | CL7: N/A | CM7: N/A | CN7: 0 | CO7: 0 | CP7: =BJ19 -> 0 | CQ7: =BK19 -> 213732 | CR7: =BL19 -> 213637 | CS7: =BM19 -> 213868 | CT7: =BN19 -> 211691
CI8: 210655 | CJ8: N/A | CK8: LAMINA GEN LACADA SIZING TIPO D 0,195 | CL8: N/A | CM8: N/A | CN8: 0 | CO8: 0 | CP8: =BJ18 -> 0 | CQ8: =BK18 -> 743 | CR8: =BL18 -> 974 | CS8: =BM18 -> 400 | CT8: =BN18 -> 1847
AI9: 1 | AJ9: 2 | AK9: 3 | AL9: 4 | AM9: 5 | AN9: 6 | AO9: 7 | AP9: 8 | AQ9: 9 | AR9: 10 | AS9: 11 | AT9: 12 | AU9: 13 | AV9: 14 | AW9: 15 | AX9: 16 | AY9: 17 | AZ9: 18 | BA9: 19 | BB9: 20 | BC9: 21 | BE9: 22 | BF9: 23 | BG9: 24 | BJ9: 25 | BK9: 26 | BL9: 27 | BM9: 28 | BN9: 29 | BU9: 32 | BV9: 33 | BW9: 34 | BX9: 35 | BY9: 36 | CG9: ENFERMERIA | CI9: 211671 | CJ9: N/A | CK9: LAMINA BASE AGUILA LACA TIPO D 0.195 | CL9: N/A | CM9: N/A | CN9: 0 | CO9: 0
AR10: =+AQ15 -> 0 | AU10: =9*1548 -> 13932 | AV10: 640 | AW10: 2313 | AX10: =1655+1300 -> 2955 | AY10: 1694 | AZ10: 371 | BA10: 310 | BK10: 743 | BL10: 974 | BM10: 400 | BQ10: VOLTEADOR DE LAMINA | BU10: =550 -> 550 | BX10: =1688+1660+1639 -> 4987 | CB10: LINEA DE REVISION | CI10: 213677 | CJ10: N/A | CK10: LAMINA LACADA SIZING PROM TIPO D 0.195 | CL10: N/A | CM10: N/A | CN10: 0 | CO10: 0 | CP10: =BJ25 -> 0 | CQ10: =BK25 -> 0 | CR10: =BL25 -> 0 | CS10: =BM25 -> 0 | CT10: =BN25 -> 0
B11: 3 | C11: 3 | E11: MACULATURA | F11: =SUM(BR13:BR18) -> 110 | BB11: 140 | BN11: 1306 | BX11: =1670+1656+1681 -> 5007 | CI11: 206454 | CJ11: N/A | CK11: LAM BASE BLANCA LACADA TIPO D 0,17 | CL11: N/A | CM11: N/A | CN11: 0 | CO11: 0 | CP11: =BJ24 -> 0 | CQ11: =BK24 -> 0 | CR11: =BL24 -> 0 | CS11: =BM24 -> 0 | CT11: =BN24 -> 0
B12: 2 | C12: 3 | I12: ZONA DE DESTAPE | R12: SACMI 1 - 2 | W12: SACMI 3 - 4 | BC12: =165 -> 165 | BN12: 541 | BX12: =1672+1642+1691 -> 5005 | CI12: 211746 | CJ12: N/A | CK12: LAM SIZING ALUM LACA OXY TIPO D 0.17 | CL12: N/A | CM12: N/A | CN12: 0 | CO12: 0
B13: 3 | C13: 3 | I13: 5 | J13: 1 | K13: 1 | L13: 1 | M13: 1 | N13: 1 | O13: 1 | P13: 1 | BQ13: M | BR13: 15 | BX13: 1663 | CI13: 207530 | CJ13: N/A | CK13: LAM GEN BASE AGUILA LACA TIPO D LG 0.17 | CL13: N/A | CM13: N/A | CN13: 0 | CO13: 0 | CP13: =BU19 -> 210655 | CQ13: =BV19 -> 0 | CR13: =BW19 -> 0 | CS13: =BX19 -> 213677 | CT13: =BY19 -> 0
B14: 1 | C14: 3 | R14: CODIGO | S14: PRODUCTO | T14: INVENTARIO | U14: ACUMULADO | V14: INVENTARIO ACTUAL | W14: CODIGO | X14: PRODUCTO | Y14: INVENTARIO | Z14: ACUMULADO | AA14: INVENTARIO ACTUAL | AI14: =SUM(AI10:AI13) -> 0 | AJ14: =SUM(AJ10:AJ13) -> 0 | AK14: =SUM(AK10:AK13) -> 0 | AL14: =SUM(AL10:AL13) -> 0 | AM14: =SUM(AM10:AM13) -> 0 | AN14: =SUM(AN10:AN13) -> 0 | AO14: =SUM(AO10:AO13) -> 0 | AP14: =SUM(AP10:AP13) -> 0 | ... BC14: =SUM(BC10:BC13) -> 165 | BE14: =SUM(BE10:BE13) -> 0 | BF14: =SUM(BF10:BF13) -> 0 | BG14: =SUM(BG10:BG13) -> 0 | BQ14: L1 | BR14: 20 | CI14: 207235 | CJ14: N/A | CK14: LAM GENERICA BASE DORADA AGUILA LIGHT | CL14: N/A | CM14: N/A | CN14: 213677 | CO14: 13932 | CP14: =BU18 -> 550 | CQ14: =BV18 -> 0 | CR14: =BW18 -> 0 | CS14: =BX18 -> 16662 | CT14: =BY18 -> 0
B15: 2 | C15: 3 | I15: NOTAS RAPIDAS | R15: =AY77 -> 213996 | S15: =VLOOKUP(R15,CI:CM,3,0) -> LAMINA AGUILA MF 2026 UV TIPO D 0,195 | T15: =SUMIF($CN:$CN,R15,$CO:$CO) -> 8602 | V15: =T15-((U15*11000)/675) -> 8602 | W15: =AY78 -> 213637 | X15: =VLOOKUP(W15,CI:CM,3,0) -> LAMINA AGUILA LGT PROMO ALFA TIP D 0.195 | Y15: =SUMIF($CN:$CN,W15,$CO:$CO) -> 25460 | AA15: =Y15-((Z15*11000)/667) -> 25460 | AU15: 213677 | AV15: 212037 | AW15: 211671 | AX15: 211749 | AY15: 210655 | AZ15: 213239 | BA15: 213995 | BB15: 212315 | BC15: 210760 | BQ15: L2 | BR15: 25 | CI15: 207542 | CJ15: N/A | CK15: LAM GEN SIZING T/RENTE LACATIP A LG 0.17 | CL15: N/A | CM15: N/A | CN15: 212037 | CO15: 640
B16: 3 | C16: 1 | U16: NUMERO DE CAJAS | Z16: NUMERO DE CAJAS | AI16: =IFERROR(VLOOKUP(AI15,$CI:$CM,3,0)," ") | AJ16: =IFERROR(VLOOKUP(AJ15,$CI:$CM,3,0)," ") | AK16: =IFERROR(VLOOKUP(AK15,$CI:$CM,3,0)," ") | AL16: =IFERROR(VLOOKUP(AL15,$CI:$CM,3,0)," ") | AM16: =IFERROR(VLOOKUP(AM15,$CI:$CM,3,0)," ") | AN16: =IFERROR(VLOOKUP(AN15,$CI:$CM,3,0)," ") | AO16: =IFERROR(VLOOKUP(AO15,$CI:$CM,3,0)," ") | AP16: =IFERROR(VLOOKUP(AP15,$CI:$CM,3,0)," ") | ... BC16: =IFERROR(VLOOKUP(BC15,$CI:$CM,3,0)," ") -> LAMINA AGUILA AZUL TIPO D 0.195 | BE16: =IFERROR(VLOOKUP(BE15,$CI:$CM,3,0)," ") | BF16: =IFERROR(VLOOKUP(BF15,$CI:$CM,3,0)," ") | BG16: =IFERROR(VLOOKUP(BG15,$CI:$CM,3,0)," ") | BQ16: L2 | BR16: 15 | CI16: 206453 | CJ16: N/A | CK16: LAMINA LACADA TIPO D LG 0,17 | CL16: N/A | CM16: N/A | CN16: 211671 | CO16: 2313 | CP16: =BU25 -> 0 | CQ16: =BV25 -> 0 | CR16: =BW25 -> 0 | CS16: =BX25 -> 0 | CT16: =BY25 -> 212037
U17: =+((V15*667)/11000) -> 521.594 | Z17: =+((AA15*667)/11000) -> 1543.8018 | AV17: SUXUN | AW17: JINTAI | AX17: SUXUN | AY17: SUXUN | AZ17: SUXUN | BB17: STEEL FORCE | BC17: STEEL FORCE | BQ17: L3 | BR17: 20 | CI17: 207544 | CJ17: N/A | CK17: LAMINA LACADA TIPO A LG 0,17 | CL17: N/A | CM17: N/A | CN17: 211749 | CO17: 2955 | CP17: =BU24 -> 0 | CQ17: =BV24 -> 0 | CR17: =BW24 -> 0 | CS17: =BX24 -> 0 | CT17: =BY24 -> 725
AV18: CLUB COLOMBIA MALA IMPRESION | AW18: COLA Y POLA | AX18: BASE BEIGE | AY18: PILSENER LACADA + SIZING | AZ18: PILSENER | BB18: COSTEÑITA CB | BC18: ÁGUILA ORIGINAL | BJ18: =SUM(BJ10:BJ17) -> 0 | BK18: =SUM(BK10:BK17) -> 743 | BL18: =SUM(BL10:BL17) -> 974 | BM18: =SUM(BM10:BM17) -> 400 | BN18: =SUM(BN10:BN17) -> 1847 | BQ18: L3 | BR18: 15 | BU18: =SUM(BU10:BU17) -> 550 | BV18: =SUM(BV10:BV17) -> 0 | BW18: =SUM(BW10:BW17) -> 0 | BX18: =SUM(BX10:BX17) -> 16662 | BY18: =SUM(BY10:BY17) -> 0 | CI18: 207532 | CJ18: N/A | CK18: LAM BASE DORADA SIZINGLACA TIPO D 0.17 | CL18: N/A | CM18: N/A | CN18: 210655 | CO18: 1694
R19: SACMI 5 - 6 | W19: SACMI 7 - 8 | BK19: 213732 | BL19: 213637 | BM19: 213868 | BN19: 211691 | BQ19: MEDIDA MACULATURA | BU19: 210655 | BX19: 213677 | CI19: 206455 | CJ19: N/A | CK19: LAM GEN SIZING T/RENTE LACA TIPO D LG 0.17 | CL19: N/A | CM19: N/A | CN19: 213239 | CO19: 371 | CP19: =BQ32 -> 0 | CQ19: =BR32 -> 0 | CR19: =BS32 -> 0 | CS19: =BT32 -> 211209 | CT19: =BU32 -> 206454 | CU19: =BV32 -> 206453 | CV19: =BW32 -> 207544 | CW19: =BX32 -> 206455 | CX19: =BY32 -> 210654
AW20: 480 | AY20: 1690 | AZ20: =1558+1680+1680 -> 4918 | BJ20: =IFERROR(VLOOKUP(BJ19,$CI:$CM,3,0)," ") | BK20: =IFERROR(VLOOKUP(BK19,$CI:$CM,3,0)," ") -> LAMINA COSTEÑA BACANA CENTRO TIPO D 0.195 | BL20: =IFERROR(VLOOKUP(BL19,$CI:$CM,3,0)," ") -> LAMINA AGUILA LGT PROMO ALFA TIP D 0.195 | BM20: =IFERROR(VLOOKUP(BM19,$CI:$CM,3,0)," ") -> LAMINA TAPA TEST CONV TIPO D0.195 | BN20: =IFERROR(VLOOKUP(BN19,$CI:$CM,3,0)," ") -> LAMINA NATIVA SUR TIPO D 0.195 | BU20: =IFERROR(VLOOKUP(BU19,$CI:$CM,3,0)," ") -> LAMINA GEN LACADA SIZING TIPO D 0,195 | BV20: =IFERROR(VLOOKUP(BV19,$CI:$CM,3,0)," ") | BW20: =IFERROR(VLOOKUP(BW19,$CI:$CM,3,0)," ") | BX20: =IFERROR(VLOOKUP(BX19,$CI:$CM,3,0)," ") -> LAMINA LACADA SIZING PROM TIPO D 0.195 | BY20: =IFERROR(VLOOKUP(BY19,$CI:$CM,3,0)," ") | CI20: 206050 | CJ20: N/A | CK20: LAM BASE BAIGE | CL20: N/A | CM20: N/A | CN20: 213995 | CO20: 310 | CP20: =BQ31 -> 0 | CQ20: =BR31 -> 0 | CR20: =BS31 -> 0 | CS20: =BT31 -> 218 | CT20: =BU31 -> 452 | CU20: =BV31 -> 1176 | CV20: =BW31 -> 4207 | CW20: =BX31 -> 6127 | CX20: =BY31 -> 9553
R21: CODIGO | S21: PRODUCTO | T21: INVENTARIO | U21: ACUMULADO | V21: INVENTARIO ACTUAL | W21: CODIGO | X21: PRODUCTO | Y21: INVENTARIO | Z21: ACUMULADO | AA21: INVENTARIO ACTUAL | AW21: 212037 | AY21: 207544 | AZ21: 210656 | BK21: STEEL FORCE | BL21: STEEL FORCE | BM21: JINTAI | BN21: JINTAI | BU21: SUXUN | BX21: SUXUN | CI21: 210760 | CJ21: 207189 | CK21: LAMINA AGUILA AZUL TIPO D 0.195 | CL21: 210655 | CM21: =VLOOKUP(CL21,$CI$2:$CK$20,3,0) -> LAMINA GEN LACADA SIZING TIPO D 0,195 | CN21: 212315 | CO21: 140
R22: =AY79 -> 213738 | S22: =VLOOKUP(R22,CI:CM,3,0) -> LAMINA POKER RENOVACION | T22: =SUMIF($CN:$CN,R22,$CO:$CO) -> 10126 | V22: =T22-((U22*11000)/667) -> 10126 | W22: =AY80 -> 212403 | X22: =VLOOKUP(W22,CI:CM,3,0) -> LAMINA COSTEÑA BACANA 2000 TP D 0.195 | Y22: =SUMIF($CN:$CN,W22,$CO:$CO) -> 6497 | AA22: =Y22-((Z22*11000)/667) -> 6497 | AI22: =IFERROR(VLOOKUP(AI21,$CI:$CM,3,0)," ") | AJ22: =IFERROR(VLOOKUP(AJ21,$CI:$CM,3,0)," ") | AK22: =IFERROR(VLOOKUP(AK21,$CI:$CM,3,0)," ") | AL22: =IFERROR(VLOOKUP(AL21,$CI:$CM,3,0)," ") | AM22: =IFERROR(VLOOKUP(AM21,$CI:$CM,3,0)," ") | AN22: =IFERROR(VLOOKUP(AN21,$CI:$CM,3,0)," ") | AO22: =IFERROR(VLOOKUP(AO21,$CI:$CM,3,0)," ") | AP22: =IFERROR(VLOOKUP(AP21,$CI:$CM,3,0)," ") | ... BC22: =IFERROR(VLOOKUP(BC21,$CI:$CM,3,0)," ") | BE22: =IFERROR(VLOOKUP(BE21,$CI:$CM,3,0)," ") | BF22: =IFERROR(VLOOKUP(BF21,$CI:$CM,3,0)," ") | BG22: =IFERROR(VLOOKUP(BG21,$CI:$CM,3,0)," ") | BK22: COSTEÑA BACANA CENTRO | BL22: LIGHT | BM22: TEST | BN22: NATIVA | BU22: LACADA ALUMINAZADA PARA ÁGUILA | BX22: BASE DORADA | CI22: 211860 | CJ22: 211877 | CK22: LAMINA ÁGUILA 330 PS TIPO D 0.195 | CL22: 210655 | CM22: =VLOOKUP(CL22,$CI$2:$CK$20,3,0) -> LAMINA GEN LACADA SIZING TIPO D 0,195 | CN22: 210760 | CO22: 165 | CP22: =BB55 -> 0 | CQ22: =BC55 -> 0 | CR22: =BD55 -> 0 | CS22: =BE55 -> 0 | CT22: =BF55 -> 0 | CU22: =BG55 -> 212127 | CV22: =BH55 -> 0 | CW22: =BI55 -> 213996 | ... DI22: =BU55 -> 212403
U23: NUMERO DE CAJAS | Z23: NUMERO DE CAJAS | AW23: SUXUN | AY23: NIPÓN | AZ23: STEEL FORCE | CI23: 211393 | CJ23: 207371 | CK23: LAMINA AGUILA LIGHT TIPO D 0.195 330 | CL23: 210655 | CM23: =VLOOKUP(CL23,$CI$2:$CK$20,3,0) -> LAMINA GEN LACADA SIZING TIPO D 0,195 | CN23: 0 | CO23: 0 | CP23: =BB54 -> 0 | CQ23: =BC54 -> 0 | CR23: =BD54 -> 0 | CS23: =BE54 -> 0 | CT23: =BF54 -> 0 | CU23: =BG54 -> 290 | CV23: =BH54 -> 0 | CW23: =BI54 -> 3060 | ... DI23: =BU54 -> 1692
U24: =+((V22*667)/11000) -> 614.00382 | Z24: =+((AA22*667)/11000) -> 393.95445 | AW24: CLUB | AY24: LACADA PARA POKER | AZ24: BASE BLANCA PONY | BY24: 725 | CG24: ALMACEN BT08 TINTAS | CI24: 211863 | CJ24: 211878 | CK24: LAMINA ÁGUILA LIGHT 330 PS TIPO D 0.195 | CL24: 210655 | CM24: =VLOOKUP(CL24,$CI$2:$CK$20,3,0) -> LAMINA GEN LACADA SIZING TIPO D 0,195 | CN24: 0 | CO24: 0
BY25: 212037 | CI25: 210761 | CJ25: 208472 | CK25: LAMINA POKER ROJA TIPO D 0.195 | CL25: 210654 | CM25: =VLOOKUP(CL25,$CI$2:$CK$20,3,0) -> LAMINA GEN LACADA TIPO D 0,195 | CN25: 0 | CO25: 0 | CP25: =AS55 -> 0 | CQ25: =AT55 -> 0 | CR25: =AU55 -> 207301 | CS25: =AV55 -> 212604
BJ26: =IFERROR(VLOOKUP(BJ25,$CI:$CM,3,0)," ") | BK26: =IFERROR(VLOOKUP(BK25,$CI:$CM,3,0)," ") | BL26: =IFERROR(VLOOKUP(BL25,$CI:$CM,3,0)," ") | BM26: =IFERROR(VLOOKUP(BM25,$CI:$CM,3,0)," ") | BN26: =IFERROR(VLOOKUP(BN25,$CI:$CM,3,0)," ") | BU26: =IFERROR(VLOOKUP(BU25,$CI:$CM,3,0)," ") | BV26: =IFERROR(VLOOKUP(BV25,$CI:$CM,3,0)," ") | BW26: =IFERROR(VLOOKUP(BW25,$CI:$CM,3,0)," ") | BX26: =IFERROR(VLOOKUP(BX25,$CI:$CM,3,0)," ") | BY26: =IFERROR(VLOOKUP(BY25,$CI:$CM,3,0)," ") -> BASE DORADA LACADA 0.195 | CI26: 211792 | CJ26: 211824 | CK26: LAMINA PILSEN QR TADA TIPO D 0.195 | CL26: 210654 | CM26: =VLOOKUP(CL26,$CI$2:$CK$20,3,0) -> LAMINA GEN LACADA TIPO D 0,195 | CN26: 0 | CO26: 0 | CP26: =AS54 -> 0 | CQ26: =AT54 -> 0 | CR26: =AU54 -> 7348 | CS26: =AV54 -> 2413
BY27: SUXUN | CI27: 212403 | CJ27: 212407 | CK27: LAMINA COSTEÑA BACANA 2000 TP D 0.195 | CL27: 210654 | CM27: =VLOOKUP(CL27,$CI$2:$CK$20,3,0) -> LAMINA GEN LACADA TIPO D 0,195 | CN27: 0 | CO27: 0
BY28: TEST CON AMARILLOS | CI28: 211691 | CJ28: 211311 | CK28: LAMINA NATIVA SUR TIPO D 0.195 | CL28: 210654 | CM28: =VLOOKUP(CL28,$CI$2:$CK$20,3,0) -> LAMINA GEN LACADA TIPO D 0,195 | CN28: 0 | CO28: 0 | CP28: =AS61 -> 206458 | CQ28: =AT61 -> 210760 | CR28: =AU61 -> 213637 | CS28: =AV61 -> 213367 | CT28: =AW61 -> 0 | CU28: =AX61 -> 0 | CV28: =AY61 -> 0 | CW28: =AZ61 -> 0 | ... DR28: =BU61 -> 0
CI29: 211672 | CJ29: 208078 | CK29: LAMINA COLA & POLA TIPO D 0.195 | CL29: 211671 | CM29: =VLOOKUP(CL29,$CI$2:$CK$20,3,0) -> LAMINA BASE AGUILA LACA TIPO D 0.195 | CN29: 0 | CO29: 0 | CP29: =AS60 -> 4693 | CQ29: =AT60 -> 4760 | CR29: =AU60 -> 1037 | CS29: =AV60 -> 520 | CT29: =AW60 -> 0 | CU29: =AX60 -> 0 | CV29: =AY60 -> 0 | CW29: =AZ60 -> 0 | ... DR29: =BU60 -> 0
CI30: 211305 | CJ30: 209630 | CK30: LAMINA YO ME CUIDO PERU TIPO D 0.195 | CL30: 210655 | CM30: =VLOOKUP(CL30,$CI$2:$CK$20,3,0) -> LAMINA GEN LACADA SIZING TIPO D 0,195 | CN30: 0 | CO30: 0
BT31: 218 | BU31: 452 | BV31: 1176 | BW31: 4207 | BX31: 6127 | BY31: =1400+1404+1878+1253+1880+1819-81 -> 9553 | CI31: 212127 | CJ31: 212195 | CK31: LAMINA YO ME CUIDO PERU ST TIPO D 0.195 | CL31: 210655 | CM31: =VLOOKUP(CL31,$CI$2:$CK$20,3,0) -> LAMINA GEN LACADA SIZING TIPO D 0,195 | CN31: 0 | CO31: 0
BT32: 211209 | BU32: 206454 | BV32: 206453 | BW32: 207544 | BX32: 206455 | BY32: 210654 | CI32: 212481 | CJ32: 209629 | CK32: LAMINA GOLDEN TIPO D 0.195 | CL32: 210655 | CM32: =VLOOKUP(CL32,$CI$2:$CK$20,3,0) -> LAMINA GEN LACADA SIZING TIPO D 0,195 | CN32: 0 | CO32: 0
BQ33: =IFERROR(VLOOKUP(BQ32,$CI:$CM,3,0)," ") | BR33: =IFERROR(VLOOKUP(BR32,$CI:$CM,3,0)," ") | BS33: =IFERROR(VLOOKUP(BS32,$CI:$CM,3,0)," ") | BT33: =IFERROR(VLOOKUP(BT32,$CI:$CM,3,0)," ") -> LAMINA CORONA MARTE TIPO D 0.195 | BU33: =IFERROR(VLOOKUP(BU32,$CI:$CM,3,0)," ") -> LAM BASE BLANCA LACADA TIPO D 0,17 | BV33: LAMINA LACADA TIPO D LG 0,17 | BW33: =IFERROR(VLOOKUP(BW32,$CI:$CM,3,0)," ") -> LAMINA LACADA TIPO A LG 0,17 | BX33: =IFERROR(VLOOKUP(BX32,$CI:$CM,3,0)," ") -> LAM GEN SIZING T/RENTE LACA TIPO D LG 0.17 | BY33: =IFERROR(VLOOKUP(BY32,$CI:$CM,3,0)," ") -> LAMINA GEN LACADA TIPO D 0,195 | CI33: 211306 | CJ33: 209631 | CK33: LAMINA CUSQUEÑA CALIDAD TIPO D 0.195 | CL33: 210655 | CM33: =VLOOKUP(CL33,$CI$2:$CK$20,3,0) -> LAMINA GEN LACADA SIZING TIPO D 0,195 | CN33: 0 | CO33: 0
BT34: STEEL FORCE | BU34: STEEL FORCE | BV34: RASSELSTEIN | BW34: NIPÓN | BX34: RASSELSTEIN | BY34: JINTAI | CI34: 212066 | CJ34: 212013 | CK34: LAMINA CC ROJA TIPO D 0.195 NEW VBI | CL34: 212037 | CM34: =VLOOKUP(CL34,$CI$2:$CK$20,3,0) -> BASE DORADA LACADA 0.195 | CN34: 0 | CO34: 0
BT35: LACA + BASE BLANCA RASELSTEIN | BU35: LACA + BASE BLANCA RASELSTEIN | BV35: LACA 0.17 | BW35: LACADA + SIZING | BX35: 0.17 LACADA +SIZING | BY35: OXIDADA | CI35: 212068 | CJ35: 212014 | CK35: LAMINA CC NEGRA TIPO D 0.195 NEW VBI | CL35: 212037 | CM35: =VLOOKUP(CL35,$CI$2:$CK$20,3,0) -> BASE DORADA LACADA 0.195 | CN35: 0 | CO35: 0
CI36: 212019 | CJ36: 212016 | CK36: LAMINA TIPO D 0.195 CLUB COLOM NEW VBI | CL36: 212037 | CM36: =VLOOKUP(CL36,$CI$2:$CK$20,3,0) -> BASE DORADA LACADA 0.195 | CN36: 0 | CO36: 0 | CQ36: CODIGO | CR36: REFERENCIA | CV36: 1 | CW36: 2 | CX36: 3 | CY36: 4 | CZ36: 5 | DA36: 6 | DB36: 7 | DC36: 8 | DD36: 9 | DE36: 10 | DF36: 11 | DG36: 12 | DH36: 13 | DI36: FISICO | DJ36: SAP | DK36: BLO
CB37: PNC LAMINA | CI37: 212378 | CJ37: 212265 | CK37: LAMINA CC OKTOBERFEST TIPOD 0.195 | CL37: 210655 | CM37: =VLOOKUP(CL37,$CI$2:$CK$20,3,0) -> LAMINA GEN LACADA SIZING TIPO D 0,195 | CN37: 0 | CO37: 0 | CQ37: 213679 | CR37: =VLOOKUP(CQ37,$CI$4:$CK$167,3,0) -> LAMINA CLUB ESMERALDA PROMOCION 0.195 | DI37: =SUM(CV37:DH37) -> 0 | DK37: =+DJ37-DI37 -> 0
CI38: 211217 | CJ38: 212080 | CK38: LAMINA BUDWEISER TW TIPO D 0.195 | CL38: 211747 | CM38: =VLOOKUP(CL38,$CI$2:$CK$20,3,0) -> LAM SIZING ALUM LACA OXY TIPO D 0.195 | CN38: 0 | CO38: 0 | CQ38: 213637 | CR38: =VLOOKUP(CQ38,$CI$4:$CK$167,3,0) -> LAMINA AGUILA LGT PROMO ALFA TIP D 0.195 | DI38: =SUM(CV38:DH38) -> 0 | DK38: =+DJ38-DI38 -> 0
B39: 1 | C39: 3 | D39: 2 | E39: 3 | F39: 3 | G39: 4 | H39: 5 | I39: 5 | CI39: 211216 | CJ39: 208453 | CK39: LAMINA PONY ROJA CI TIPO D 0.195 | CL39: 210654 | CM39: =VLOOKUP(CL39,$CI$2:$CK$20,3,0) -> LAMINA GEN LACADA TIPO D 0,195 | CN39: 0 | CO39: 0 | CQ39: 213738 | CR39: =VLOOKUP(CQ39,$CI$4:$CK$167,3,0) -> LAMINA POKER RENOVACION | CV39: 360 | CW39: 1301 | CX39: 940 | CY39: 451 | CZ39: 1918 | DA39: 1490 | DI39: =SUM(CV39:DH39) -> 6460 | DK39: =+DJ39-DI39 -> -6460
CG40: OFICINA ASL, SLI | CI40: 212315 | CJ40: 202732 | CK40: LAMINA COSTEÑITA CBARRAS LG TIPOD.0.195 | CL40: 210655 | CM40: =VLOOKUP(CL40,$CI$2:$CK$20,3,0) -> LAMINA GEN LACADA SIZING TIPO D 0,195 | CN40: 0 | CO40: 0 | CQ40: 211306 | CR40: =VLOOKUP(CQ40,$CI$4:$CK$167,3,0) -> LAMINA CUSQUEÑA CALIDAD TIPO D 0.195 | CV40: 280 | CW40: 1252 | DI40: =SUM(CV40:DH40) -> 1532 | DK40: =+DJ40-DI40 -> -1532
...

Sheet DATA
A1: CODIGO | B1: CANTIDAD | C1: DESCCRIPCION | D1: PROVEEDOR | E1: MODULO
A2: ='MODELO LAYOUT'!$AI$15 -> 0 | B2: ='MODELO LAYOUT'!$AI$14 -> 0 | C2: ='MODELO LAYOUT'!AI18 -> 0 | D2: ='MODELO LAYOUT'!AI17 -> 0 | E2: ='MODELO LAYOUT'!AI9 -> 1
A3: ='MODELO LAYOUT'!$AJ$15 -> 0 | B3: ='MODELO LAYOUT'!$AJ$14 -> 0 | C3: ='MODELO LAYOUT'!AJ18 -> 0 | D3: ='MODELO LAYOUT'!AJ17 -> 0 | E3: ='MODELO LAYOUT'!AJ9 -> 2
A4: ='MODELO LAYOUT'!$AK$15 -> 0 | B4: ='MODELO LAYOUT'!$AK$14 -> 0 | C4: ='MODELO LAYOUT'!AK18 -> 0 | D4: ='MODELO LAYOUT'!AK17 -> 0 | E4: ='MODELO LAYOUT'!AK9 -> 3
A5: ='MODELO LAYOUT'!$AL$15 -> 0 | B5: ='MODELO LAYOUT'!$AL$14 -> 0 | C5: ='MODELO LAYOUT'!AL18 -> 0 | D5: ='MODELO LAYOUT'!AL17 -> 0 | E5: ='MODELO LAYOUT'!AL9 -> 4
A6: ='MODELO LAYOUT'!$AM$15 -> 0 | B6: ='MODELO LAYOUT'!$AM$14 -> 0 | C6: ='MODELO LAYOUT'!AM18 -> 0 | D6: ='MODELO LAYOUT'!AM17 -> 0 | E6: ='MODELO LAYOUT'!AM9 -> 5
A7: ='MODELO LAYOUT'!$AN$15 -> 0 | B7: ='MODELO LAYOUT'!$AN$14 -> 0 | C7: ='MODELO LAYOUT'!AN18 -> 0 | D7: ='MODELO LAYOUT'!AN17 -> 0 | E7: ='MODELO LAYOUT'!AN9 -> 6
A8: ='MODELO LAYOUT'!$AO$15 -> 0 | B8: ='MODELO LAYOUT'!$AO$14 -> 0 | C8: ='MODELO LAYOUT'!AO18 -> 0 | D8: ='MODELO LAYOUT'!AO1 -> 0 | E8: ='MODELO LAYOUT'!AO9 -> 7
A9: ='MODELO LAYOUT'!$AP$15 -> 0 | B9: ='MODELO LAYOUT'!$AP$14 -> 0 | C9: ='MODELO LAYOUT'!AP18 -> 0 | D9: ='MODELO LAYOUT'!AP17 -> 0 | E9: ='MODELO LAYOUT'!AP9 -> 8
A10: ='MODELO LAYOUT'!$AQ$15 -> 0 | B10: ='MODELO LAYOUT'!$AQ$14 -> 0 | C10: ='MODELO LAYOUT'!AQ18 -> 0 | D10: ='MODELO LAYOUT'!AQ17 -> 0 | E10: ='MODELO LAYOUT'!AQ9 -> 9
A11: ='MODELO LAYOUT'!$AR$15 -> 0 | B11: ='MODELO LAYOUT'!$AR$14 -> 0 | C11: ='MODELO LAYOUT'!AR18 -> 0 | D11: ='MODELO LAYOUT'!AR17 -> 0 | E11: ='MODELO LAYOUT'!AR9 -> 10
A12: ='MODELO LAYOUT'!$AS$15 -> 0 | B12: ='MODELO LAYOUT'!$AS$14 -> 0 | C12: ='MODELO LAYOUT'!AS18 -> 0 | D12: ='MODELO LAYOUT'!AS17 -> 0 | E12: ='MODELO LAYOUT'!AS9 -> 11
A13: ='MODELO LAYOUT'!$AT$15 -> 0 | B13: ='MODELO LAYOUT'!$AT$14 -> 0 | C13: ='MODELO LAYOUT'!AT18 -> 0 | D13: ='MODELO LAYOUT'!AT17 -> 0 | E13: ='MODELO LAYOUT'!AT9 -> 12
A14: ='MODELO LAYOUT'!$AU$15 -> 213677 | B14: ='MODELO LAYOUT'!$AU$14 -> 13932 | C14: ='MODELO LAYOUT'!AU18 -> 0 | D14: ='MODELO LAYOUT'!AU17 -> 0 | E14: ='MODELO LAYOUT'!AU9 -> 13
A15: ='MODELO LAYOUT'!$AV$15 -> 212037 | B15: ='MODELO LAYOUT'!$AV$14 -> 640 | C15: ='MODELO LAYOUT'!AV18 -> CLUB COLOMBIA MALA IMPRESION | D15: ='MODELO LAYOUT'!AV17 -> SUXUN | E15: ='MODELO LAYOUT'!AV9 -> 14
A16: ='MODELO LAYOUT'!$AW$15 -> 211671 | B16: ='MODELO LAYOUT'!$AW$14 -> 2313 | C16: ='MODELO LAYOUT'!AW18 -> COLA Y POLA | D16: ='MODELO LAYOUT'!AW17 -> JINTAI | E16: ='MODELO LAYOUT'!AW9 -> 15
A17: ='MODELO LAYOUT'!$AX$15 -> 211749 | B17: ='MODELO LAYOUT'!$AX$14 -> 2955 | C17: ='MODELO LAYOUT'!AX18 -> BASE BEIGE | D17: ='MODELO LAYOUT'!AX17 -> SUXUN | E17: ='MODELO LAYOUT'!AX9 -> 16
A18: ='MODELO LAYOUT'!$AY$15 -> 210655 | B18: ='MODELO LAYOUT'!$AY$14 -> 1694 | C18: ='MODELO LAYOUT'!AY18 -> PILSENER LACADA + SIZING | D18: ='MODELO LAYOUT'!AY17 -> SUXUN | E18: ='MODELO LAYOUT'!AY9 -> 17
A19: ='MODELO LAYOUT'!$AZ$15 -> 213239 | B19: ='MODELO LAYOUT'!$AZ$14 -> 371 | C19: ='MODELO LAYOUT'!AZ18 -> PILSENER | D19: ='MODELO LAYOUT'!AZ17 -> SUXUN | E19: ='MODELO LAYOUT'!AZ9 -> 18
A20: ='MODELO LAYOUT'!$BA$15 -> 213995 | B20: ='MODELO LAYOUT'!$BA$14 -> 310 | C20: ='MODELO LAYOUT'!BA18 -> 0 | D20: ='MODELO LAYOUT'!BA17 -> 0 | E20: ='MODELO LAYOUT'!BA9 -> 19
A21: ='MODELO LAYOUT'!$BB$15 -> 212315 | B21: ='MODELO LAYOUT'!$BB$14 -> 140 | C21: ='MODELO LAYOUT'!BB18 -> COSTEÑITA CB | D21: ='MODELO LAYOUT'!BB17 -> STEEL FORCE | E21: ='MODELO LAYOUT'!BB9 -> 20
A22: ='MODELO LAYOUT'!$BC$15 -> 210760 | B22: ='MODELO LAYOUT'!$BC$14 -> 165 | C22: ='MODELO LAYOUT'!BC18 -> ÁGUILA ORIGINAL | D22: ='MODELO LAYOUT'!BC17 -> STEEL FORCE | E22: ='MODELO LAYOUT'!BC9 -> 21
A23: ='MODELO LAYOUT'!$AI$21 -> 0 | B23: ='MODELO LAYOUT'!AI$20 -> 0 | C23: ='MODELO LAYOUT'!AI24 -> 0 | D23: ='MODELO LAYOUT'!AI23 | E23: ='MODELO LAYOUT'!AI25 -> 0
A24: ='MODELO LAYOUT'!$AJ$21 -> 0 | B24: ='MODELO LAYOUT'!$AJ$20 -> 0 | C24: ='MODELO LAYOUT'!AJ24 -> 0 | D24: ='MODELO LAYOUT'!AJ23 -> 0 | E24: ='MODELO LAYOUT'!AJ25 -> 0
A25: ='MODELO LAYOUT'!$AK$21 -> 0 | B25: ='MODELO LAYOUT'!$AK$20 -> 0 | C25: ='MODELO LAYOUT'!AK24 -> 0 | D25: ='MODELO LAYOUT'!AK23 -> 0 | E25: ='MODELO LAYOUT'!AK25 -> 0
A26: ='MODELO LAYOUT'!$AL$21 -> 0 | B26: ='MODELO LAYOUT'!$AL$20 -> 0 | C26: ='MODELO LAYOUT'!AL24 -> 0 | D26: ='MODELO LAYOUT'!AL23 -> 0 | E26: ='MODELO LAYOUT'!AL25 -> 0
A27: ='MODELO LAYOUT'!$AM$21 -> 0 | B27: ='MODELO LAYOUT'!$AM$20 -> 0 | C27: ='MODELO LAYOUT'!AM24 -> 0 | D27: ='MODELO LAYOUT'!AM23 -> 0 | E27: ='MODELO LAYOUT'!AM25 -> 0
A28: ='MODELO LAYOUT'!AN$21 -> 0 | B28: ='MODELO LAYOUT'!$AN$20 -> 0 | C28: ='MODELO LAYOUT'!AN24 -> 0 | D28: ='MODELO LAYOUT'!AN23 -> 0 | E28: ='MODELO LAYOUT'!AN25 -> 0
A29: ='MODELO LAYOUT'!$AO$21 -> 0 | B29: ='MODELO LAYOUT'!$AO$20 -> 0 | C29: ='MODELO LAYOUT'!AO24 -> 0 | D29: ='MODELO LAYOUT'!AO23 -> 0 | E29: ='MODELO LAYOUT'!AO25 -> 0
A30: ='MODELO LAYOUT'!$AP$21 -> 0 | B30: ='MODELO LAYOUT'!$AP$20 -> 0 | C30: ='MODELO LAYOUT'!AP24 -> 0 | D30: ='MODELO LAYOUT'!AP23 -> 0 | E30: ='MODELO LAYOUT'!AP25 -> 0
A31: ='MODELO LAYOUT'!$AQ$21 -> 0 | B31: ='MODELO LAYOUT'!$AQ$20 -> 0 | C31: ='MODELO LAYOUT'!AQ24 -> 0 | D31: ='MODELO LAYOUT'!AQ23 -> 0 | E31: ='MODELO LAYOUT'!AQ25 -> 0
A32: ='MODELO LAYOUT'!$AR$21 -> 0 | B32: ='MODELO LAYOUT'!$AR$20 -> 0 | C32: ='MODELO LAYOUT'!AR24 -> 0 | D32: ='MODELO LAYOUT'!AR23 -> 0 | E32: ='MODELO LAYOUT'!AR25 -> 0
A33: ='MODELO LAYOUT'!$AS$21 -> 0 | B33: ='MODELO LAYOUT'!$AS$20 -> 0 | C33: ='MODELO LAYOUT'!AS24 -> 0 | D33: ='MODELO LAYOUT'!AS23 -> 0 | E33: ='MODELO LAYOUT'!AS25 -> 0
A34: ='MODELO LAYOUT'!$AT$21 -> 0 | B34: ='MODELO LAYOUT'!$AT$20 -> 0 | C34: ='MODELO LAYOUT'!AT24 -> 0 | D34: ='MODELO LAYOUT'!AT23 -> 0 | E34: ='MODELO LAYOUT'!AT25 -> 0
A35: ='MODELO LAYOUT'!$AU$21 -> 0 | B35: ='MODELO LAYOUT'!$AU$20 -> 0 | C35: ='MODELO LAYOUT'!AU24 -> 0 | D35: ='MODELO LAYOUT'!AU23 -> 0 | E35: ='MODELO LAYOUT'!AU25 -> 0
A36: ='MODELO LAYOUT'!$AV$21 -> 0 | B36: ='MODELO LAYOUT'!$AV$20 -> 0 | C36: ='MODELO LAYOUT'!AV24 -> 0 | D36: ='MODELO LAYOUT'!AV23 -> 0 | E36: ='MODELO LAYOUT'!AV25 -> 0
A37: ='MODELO LAYOUT'!$AW$21 -> 212037 | B37: ='MODELO LAYOUT'!$AW$20 -> 480 | C37: ='MODELO LAYOUT'!AW24 -> CLUB | D37: ='MODELO LAYOUT'!AW23 -> SUXUN | E37: ='MODELO LAYOUT'!AW25 -> 0
A38: ='MODELO LAYOUT'!$AX$21 -> 0 | B38: ='MODELO LAYOUT'!$AX$20 -> 0 | C38: ='MODELO LAYOUT'!AX24 -> 0 | D38: ='MODELO LAYOUT'!AX23 -> 0 | E38: ='MODELO LAYOUT'!AX25 -> 0
A39: ='MODELO LAYOUT'!$AY$21 -> 207544 | B39: ='MODELO LAYOUT'!$AY$20 -> 1690 | C39: ='MODELO LAYOUT'!AY24 -> LACADA PARA POKER | D39: ='MODELO LAYOUT'!AY23 -> NIPÓN | E39: ='MODELO LAYOUT'!AY25 -> 0
A40: ='MODELO LAYOUT'!$AZ$21 -> 210656 | B40: ='MODELO LAYOUT'!$AZ$20 -> 4918 | C40: ='MODELO LAYOUT'!AZ24 -> BASE BLANCA PONY | D40: ='MODELO LAYOUT'!AZ23 -> STEEL FORCE | E40: ='MODELO LAYOUT'!AZ25 -> 0
...
